Workbook
Name MyTable: Sales7[]
Name Slicer_Region: #N/A

Sheet Sales_Transactions
A1: Order ID | B1: Order Date | C1: Product ID | D1: Employee ID | E1: Units Sold
A2: 1009 | B2: 44928 | C2: P04 | D2: E06 | E2: 1
A3: 1004 | B3: 44930 | C3: P04 | D3: E03 | E3: 3
A4: 1001 | B4: 44934 | C4: P09 | D4: E04 | E4: 4
A5: 1003 | B5: 44935 | C5: P07 | D5: E03 | E5: 3
A6: 1011 | B6: 44935 | C6: P02 | D6: E04 | E6: 4
A7: 1013 | B7: 44935 | C7: P04 | D7: E06 | E7: 10
A8: 1018 | B8: 44935 | C8: P06 | D8: E01 | E8: 4
A9: 1021 | B9: 44935 | C9: P08 | D9: E07 | E9: 1
A10: 1008 | B10: 44936 | C10: P02 | D10: E07 | E10: 6
A11: 1005 | B11: 44938 | C11: P07 | D11: E02 | E11: 1
A12: 1012 | B12: 44938 | C12: P06 | D12: E08 | E12: 1
A13: 1015 | B13: 44939 | C13: P03 | D13: E04 | E13: 5
... A743: 1726 | B743: 45657 | C743: P07 | D743: E01 | E743: 3

Sheet Product_Master
A1: Product ID | B1: Product Name | C1: Category | D1: Unit Price (₹)
A2: P01 | B2: Wireless Mouse | C2: Electronics | D2: 780
A3: P02 | B3: Bluetooth Speaker | C3: Electronics | D3: 1430
A4: P03 | B4: LED Monitor 24" | C4: Electronics | D4: 7700
A5: P04 | B5: Ergo Office Chair | C5: Office Supplies | D5: 6750
A6: P05 | B6: Standing Desk | C6: Office Supplies | D6: 11010
A7: P06 | B7: Bookshelf Unit | C7: Furniture | D7: 3910
A8: P07 | B8: Filing Cabinet | C8: Furniture | D8: 4070
A9: P08 | B9: Laptop Backpack | C9: Accessories | D9: 1110
A10: P09 | B10: USB-C Hub | C10: Accessories | D10: 880

Sheet Salesperson_Master
A1: Employee ID | B1: Salesperson | C1: Region | D1: State/City
A2: E01 | B2: Aarav Sharma | C2: North | D2: Lucknow
A3: E02 | B3: Ishita Verma | C3: North | D3: Chandigarh
A4: E03 | B4: Rohan Mehta | C4: South | D4: Bengaluru
A5: E04 | B5: Priya Nair | C5: South | D5: Bengaluru
A6: E05 | B6: Karan Malhotra | C6: East | D6: Kolkata
A7: E06 | B7: Sneha Roy | C7: East | D7: Kolkata
A8: E07 | B8: Aditya Kapoor | C8: West | D8: Mumbai
A9: E08 | B9: Neha Joshi | C9: West | D9: Ahmedabad

Sheet Monthly_Targets
A1: Month | B1: Region | C1: Revenue Target (₹)
A2: 44927 | B2: North | C2: 550000
A3: 44927 | B3: South | C3: 620000
A4: 44927 | B4: East | C4: 400000
A5: 44927 | B5: West | C5: 580000
A6: 44958 | B6: North | C6: 550000
A7: 44958 | B7: South | C7: 620000
A8: 44958 | B8: East | C8: 400000
A9: 44958 | B9: West | C9: 580000
A10: 44986 | B10: North | C10: 550000
A11: 44986 | B11: South | C11: 620000
A12: 44986 | B12: East | C12: 400000
A13: 44986 | B13: West | C13: 580000
... A97: 45627 | B97: West | C97: 742000

Sheet Merged_Sales_Data
A1: Order ID | B1: Order Date | C1: Product ID | D1: Product Name | E1: Category | F1: Unit Price (₹) | G1: Employee ID | H1: Salesperson | I1: Region | J1: State/City | K1: Units Sold | L1: Revenue (₹)
A2: 1009 | B2: 44928 | C2: P04 | D2: =_xlfn.XLOOKUP(Merged_Sales_Data!C2,PM[Product ID],PM[Product Name]) -> Ergo Office Chair | E2: =VLOOKUP(C2,PM[],3,FALSE) -> Office Supplies | F2: =_xlfn.XLOOKUP(C2,PM[Product ID],PM[Unit Price (₹)]) -> 6750 | G2: E07 | H2: =_xlfn.XLOOKUP(G2,SM[Employee ID],SM[Salesperson]) -> Aditya Kapoor | I2: =_xlfn.XLOOKUP(G2,SM[Employee ID],SM[Region]) -> West | J2: =_xlfn.XLOOKUP(G2,SM[Employee ID],SM[State/City]) -> Mumbai | K2: 1 | L2: =F2*K2 -> 6750
A3: 1004 | B3: 44930 | C3: P04 | D3: =_xlfn.XLOOKUP(Merged_Sales_Data!C3,PM[Product ID],PM[Product Name]) -> Ergo Office Chair | E3: =VLOOKUP(C3,PM[],3,FALSE) -> Office Supplies | F3: =_xlfn.XLOOKUP(C3,PM[Product ID],PM[Unit Price (₹)]) -> 6750 | G3: E06 | H3: =_xlfn.XLOOKUP(G3,SM[Employee ID],SM[Salesperson]) -> Sneha Roy | I3: =_xlfn.XLOOKUP(G3,SM[Employee ID],SM[Region]) -> East | J3: =_xlfn.XLOOKUP(G3,SM[Employee ID],SM[State/City]) -> Kolkata | K3: 1 | L3: =F3*K3 -> 6750
A4: 1001 | B4: 44934 | C4: P09 | D4: =_xlfn.XLOOKUP(Merged_Sales_Data!C4,PM[Product ID],PM[Product Name]) -> USB-C Hub | E4: =VLOOKUP(C4,PM[],3,FALSE) -> Accessories | F4: =_xlfn.XLOOKUP(C4,PM[Product ID],PM[Unit Price (₹)]) -> 880 | G4: E08 | H4: =_xlfn.XLOOKUP(G4,SM[Employee ID],SM[Salesperson]) -> Neha Joshi | I4: =_xlfn.XLOOKUP(G4,SM[Employee ID],SM[Region]) -> West | J4: =_xlfn.XLOOKUP(G4,SM[Employee ID],SM[State/City]) -> Ahmedabad | K4: 6 | L4: =F4*K4 -> 5280
A5: 1003 | B5: 44935 | C5: P07 | D5: =_xlfn.XLOOKUP(Merged_Sales_Data!C5,PM[Product ID],PM[Product Name]) -> Filing Cabinet | E5: =VLOOKUP(C5,PM[],3,FALSE) -> Furniture | F5: =_xlfn.XLOOKUP(C5,PM[Product ID],PM[Unit Price (₹)]) -> 4070 | G5: E08 | H5: =_xlfn.XLOOKUP(G5,SM[Employee ID],SM[Salesperson]) -> Neha Joshi | I5: =_xlfn.XLOOKUP(G5,SM[Employee ID],SM[Region]) -> West | J5: =_xlfn.XLOOKUP(G5,SM[Employee ID],SM[State/City]) -> Ahmedabad | K5: 6 | L5: =F5*K5 -> 24420
A6: 1011 | B6: 44935 | C6: P02 | D6: =_xlfn.XLOOKUP(Merged_Sales_Data!C6,PM[Product ID],PM[Product Name]) -> Bluetooth Speaker | E6: =VLOOKUP(C6,PM[],3,FALSE) -> Electronics | F6: =_xlfn.XLOOKUP(C6,PM[Product ID],PM[Unit Price (₹)]) -> 1430 | G6: E06 | H6: =_xlfn.XLOOKUP(G6,SM[Employee ID],SM[Salesperson]) -> Sneha Roy | I6: =_xlfn.XLOOKUP(G6,SM[Employee ID],SM[Region]) -> East | J6: =_xlfn.XLOOKUP(G6,SM[Employee ID],SM[State/City]) -> Kolkata | K6: 10 | L6: =F6*K6 -> 14300 | O6: =SUM(Sales[Order ID]) -> 1017653
A7: 1013 | B7: 44935 | C7: P04 | D7: =_xlfn.XLOOKUP(Merged_Sales_Data!C7,PM[Product ID],PM[Product Name]) -> Ergo Office Chair | E7: =VLOOKUP(C7,PM[],3,FALSE) -> Office Supplies | F7: =_xlfn.XLOOKUP(C7,PM[Product ID],PM[Unit Price (₹)]) -> 6750 | G7: E06 | H7: =_xlfn.XLOOKUP(G7,SM[Employee ID],SM[Salesperson]) -> Sneha Roy | I7: =_xlfn.XLOOKUP(G7,SM[Employee ID],SM[Region]) -> East | J7: =_xlfn.XLOOKUP(G7,SM[Employee ID],SM[State/City]) -> Kolkata | K7: 8 | L7: =F7*K7 -> 54000
A8: 1018 | B8: 44935 | C8: P06 | D8: =_xlfn.XLOOKUP(Merged_Sales_Data!C8,PM[Product ID],PM[Product Name]) -> Bookshelf Unit | E8: =VLOOKUP(C8,PM[],3,FALSE) -> Furniture | F8: =_xlfn.XLOOKUP(C8,PM[Product ID],PM[Unit Price (₹)]) -> 3910 | G8: E08 | H8: =_xlfn.XLOOKUP(G8,SM[Employee ID],SM[Salesperson]) -> Neha Joshi | I8: =_xlfn.XLOOKUP(G8,SM[Employee ID],SM[Region]) -> West | J8: =_xlfn.XLOOKUP(G8,SM[Employee ID],SM[State/City]) -> Ahmedabad | K8: 4 | L8: =F8*K8 -> 15640
A9: 1021 | B9: 44935 | C9: P08 | D9: =_xlfn.XLOOKUP(Merged_Sales_Data!C9,PM[Product ID],PM[Product Name]) -> Laptop Backpack | E9: =VLOOKUP(C9,PM[],3,FALSE) -> Accessories | F9: =_xlfn.XLOOKUP(C9,PM[Product ID],PM[Unit Price (₹)]) -> 1110 | G9: E04 | H9: =_xlfn.XLOOKUP(G9,SM[Employee ID],SM[Salesperson]) -> Priya Nair | I9: =_xlfn.XLOOKUP(G9,SM[Employee ID],SM[Region]) -> South | J9: =_xlfn.XLOOKUP(G9,SM[Employee ID],SM[State/City]) -> Bengaluru | K9: 1 | L9: =F9*K9 -> 1110
A10: 1008 | B10: 44936 | C10: P02 | D10: =_xlfn.XLOOKUP(Merged_Sales_Data!C10,PM[Product ID],PM[Product Name]) -> Bluetooth Speaker | E10: =VLOOKUP(C10,PM[],3,FALSE) -> Electronics | F10: =_xlfn.XLOOKUP(C10,PM[Product ID],PM[Unit Price (₹)]) -> 1430 | G10: E05 | H10: =_xlfn.XLOOKUP(G10,SM[Employee ID],SM[Salesperson]) -> Karan Malhotra | I10: =_xlfn.XLOOKUP(G10,SM[Employee ID],SM[Region]) -> East | J10: =_xlfn.XLOOKUP(G10,SM[Employee ID],SM[State/City]) -> Kolkata | K10: 4 | L10: =F10*K10 -> 5720
A11: 1005 | B11: 44938 | C11: P07 | D11: =_xlfn.XLOOKUP(Merged_Sales_Data!C11,PM[Product ID],PM[Product Name]) -> Filing Cabinet | E11: =VLOOKUP(C11,PM[],3,FALSE) -> Furniture | F11: =_xlfn.XLOOKUP(C11,PM[Product ID],PM[Unit Price (₹)]) -> 4070 | G11: E02 | H11: =_xlfn.XLOOKUP(G11,SM[Employee ID],SM[Salesperson]) -> Ishita Verma | I11: =_xlfn.XLOOKUP(G11,SM[Employee ID],SM[Region]) -> North | J11: =_xlfn.XLOOKUP(G11,SM[Employee ID],SM[State/City]) -> Chandigarh | K11: 2 | L11: =F11*K11 -> 8140
A12: 1012 | B12: 44938 | C12: P06 | D12: =_xlfn.XLOOKUP(Merged_Sales_Data!C12,PM[Product ID],PM[Product Name]) -> Bookshelf Unit | E12: =VLOOKUP(C12,PM[],3,FALSE) -> Furniture | F12: =_xlfn.XLOOKUP(C12,PM[Product ID],PM[Unit Price (₹)]) -> 3910 | G12: E03 | H12: =_xlfn.XLOOKUP(G12,SM[Employee ID],SM[Salesperson]) -> Rohan Mehta | I12: =_xlfn.XLOOKUP(G12,SM[Employee ID],SM[Region]) -> South | J12: =_xlfn.XLOOKUP(G12,SM[Employee ID],SM[State/City]) -> Bengaluru | K12: 10 | L12: =F12*K12 -> 39100
A13: 1015 | B13: 44939 | C13: P03 | D13: =_xlfn.XLOOKUP(Merged_Sales_Data!C13,PM[Product ID],PM[Product Name]) -> LED Monitor 24" | E13: =VLOOKUP(C13,PM[],3,FALSE) -> Electronics | F13: =_xlfn.XLOOKUP(C13,PM[Product ID],PM[Unit Price (₹)]) -> 7700 | G13: E07 | H13: =_xlfn.XLOOKUP(G13,SM[Employee ID],SM[Salesperson]) -> Aditya Kapoor | I13: =_xlfn.XLOOKUP(G13,SM[Employee ID],SM[Region]) -> West | J13: =_xlfn.XLOOKUP(G13,SM[Employee ID],SM[State/City]) -> Mumbai | K13: 2 | L13: =F13*K13 -> 15400
A14: 1020 | B14: 44942 | C14: P04 | D14: =_xlfn.XLOOKUP(Merged_Sales_Data!C14,PM[Product ID],PM[Product Name]) -> Ergo Office Chair | E14: =VLOOKUP(C14,PM[],3,FALSE) -> Office Supplies | F14: =_xlfn.XLOOKUP(C14,PM[Product ID],PM[Unit Price (₹)]) -> 6750 | G14: E05 | H14: =_xlfn.XLOOKUP(G14,SM[Employee ID],SM[Salesperson]) -> Karan Malhotra | I14: =_xlfn.XLOOKUP(G14,SM[Employee ID],SM[Region]) -> East | J14: =_xlfn.XLOOKUP(G14,SM[Employee ID],SM[State/City]) -> Kolkata | K14: 6 | L14: =F14*K14 -> 40500
A15: 1022 | B15: 44944 | C15: P04 | D15: =_xlfn.XLOOKUP(Merged_Sales_Data!C15,PM[Product ID],PM[Product Name]) -> Ergo Office Chair | E15: =VLOOKUP(C15,PM[],3,FALSE) -> Office Supplies | F15: =_xlfn.XLOOKUP(C15,PM[Product ID],PM[Unit Price (₹)]) -> 6750 | G15: E07 | H15: =_xlfn.XLOOKUP(G15,SM[Employee ID],SM[Salesperson]) -> Aditya Kapoor | I15: =_xlfn.XLOOKUP(G15,SM[Employee ID],SM[Region]) -> West | J15: =_xlfn.XLOOKUP(G15,SM[Employee ID],SM[State/City]) -> Mumbai | K15: 1 | L15: =F15*K15 -> 6750
A16: 1016 | B16: 44948 | C16: P09 | D16: =_xlfn.XLOOKUP(Merged_Sales_Data!C16,PM[Product ID],PM[Product Name]) -> USB-C Hub | E16: =VLOOKUP(C16,PM[],3,FALSE) -> Accessories | F16: =_xlfn.XLOOKUP(C16,PM[Product ID],PM[Unit Price (₹)]) -> 880 | G16: E06 | H16: =_xlfn.XLOOKUP(G16,SM[Employee ID],SM[Salesperson]) -> Sneha Roy | I16: =_xlfn.XLOOKUP(G16,SM[Employee ID],SM[Region]) -> East | J16: =_xlfn.XLOOKUP(G16,SM[Employee ID],SM[State/City]) -> Kolkata | K16: 10 | L16: =F16*K16 -> 8800
A17: 1006 | B17: 44950 | C17: P05 | D17: =_xlfn.XLOOKUP(Merged_Sales_Data!C17,PM[Product ID],PM[Product Name]) -> Standing Desk | E17: =VLOOKUP(C17,PM[],3,FALSE) -> Office Supplies | F17: =_xlfn.XLOOKUP(C17,PM[Product ID],PM[Unit Price (₹)]) -> 11010 | G17: E07 | H17: =_xlfn.XLOOKUP(G17,SM[Employee ID],SM[Salesperson]) -> Aditya Kapoor | I17: =_xlfn.XLOOKUP(G17,SM[Employee ID],SM[Region]) -> West | J17: =_xlfn.XLOOKUP(G17,SM[Employee ID],SM[State/City]) -> Mumbai | K17: 1 | L17: =F17*K17 -> 11010
A18: 1014 | B18: 44950 | C18: P03 | D18: =_xlfn.XLOOKUP(Merged_Sales_Data!C18,PM[Product ID],PM[Product Name]) -> LED Monitor 24" | E18: =VLOOKUP(C18,PM[],3,FALSE) -> Electronics | F18: =_xlfn.XLOOKUP(C18,PM[Product ID],PM[Unit Price (₹)]) -> 7700 | G18: E01 | H18: =_xlfn.XLOOKUP(G18,SM[Employee ID],SM[Salesperson]) -> Aarav Sharma | I18: =_xlfn.XLOOKUP(G18,SM[Employee ID],SM[Region]) -> North | J18: =_xlfn.XLOOKUP(G18,SM[Employee ID],SM[State/City]) -> Lucknow | K18: 1 | L18: =F18*K18 -> 7700
A19: 1002 | B19: 44951 | C19: P05 | D19: =_xlfn.XLOOKUP(Merged_Sales_Data!C19,PM[Product ID],PM[Product Name]) -> Standing Desk | E19: =VLOOKUP(C19,PM[],3,FALSE) -> Office Supplies | F19: =_xlfn.XLOOKUP(C19,PM[Product ID],PM[Unit Price (₹)]) -> 11010 | G19: E01 | H19: =_xlfn.XLOOKUP(G19,SM[Employee ID],SM[Salesperson]) -> Aarav Sharma | I19: =_xlfn.XLOOKUP(G19,SM[Employee ID],SM[Region]) -> North | J19: =_xlfn.XLOOKUP(G19,SM[Employee ID],SM[State/City]) -> Lucknow | K19: 3 | L19: =F19*K19 -> 33030
A20: 1017 | B20: 44953 | C20: P01 | D20: =_xlfn.XLOOKUP(Merged_Sales_Data!C20,PM[Product ID],PM[Product Name]) -> Wireless Mouse | E20: =VLOOKUP(C20,PM[],3,FALSE) -> Electronics | F20: =_xlfn.XLOOKUP(C20,PM[Product ID],PM[Unit Price (₹)]) -> 780 | G20: =_xlfn.XLOOKUP(Sales[[#This Row],[Order ID]],ST[Order ID],ST[Employee ID]) -> E06 | H20: =_xlfn.XLOOKUP(G20,SM[Employee ID],SM[Salesperson]) -> Sneha Roy | I20: =_xlfn.XLOOKUP(G20,SM[Employee ID],SM[Region]) -> East | J20: =_xlfn.XLOOKUP(G20,SM[Employee ID],SM[State/City]) -> Kolkata | K20: =_xlfn.XLOOKUP(Sales[[#This Row],[Order ID]],ST[Order ID],ST[Units Sold]) -> 2 | L20: =F20*K20 -> 1560
A21: 1010 | B21: 44954 | C21: P05 | D21: =_xlfn.XLOOKUP(Merged_Sales_Data!C21,PM[Product ID],PM[Product Name]) -> Standing Desk | E21: =VLOOKUP(C21,PM[],3,FALSE) -> Office Supplies | F21: =_xlfn.XLOOKUP(C21,PM[Product ID],PM[Unit Price (₹)]) -> 11010 | G21: =_xlfn.XLOOKUP(Sales[[#This Row],[Order ID]],ST[Order ID],ST[Employee ID]) -> E04 | H21: =_xlfn.XLOOKUP(G21,SM[Employee ID],SM[Salesperson]) -> Priya Nair | I21: =_xlfn.XLOOKUP(G21,SM[Employee ID],SM[Region]) -> South | J21: =_xlfn.XLOOKUP(G21,SM[Employee ID],SM[State/City]) -> Bengaluru | K21: =_xlfn.XLOOKUP(Sales[[#This Row],[Order ID]],ST[Order ID],ST[Units Sold]) -> 1 | L21: =F21*K21 -> 11010
A22: 1019 | B22: 44955 | C22: P04 | D22: =_xlfn.XLOOKUP(Merged_Sales_Data!C22,PM[Product ID],PM[Product Name]) -> Ergo Office Chair | E22: =VLOOKUP(C22,PM[],3,FALSE) -> Office Supplies | F22: =_xlfn.XLOOKUP(C22,PM[Product ID],PM[Unit Price (₹)]) -> 6750 | G22: =_xlfn.XLOOKUP(Sales[[#This Row],[Order ID]],ST[Order ID],ST[Employee ID]) -> E02 | H22: =_xlfn.XLOOKUP(G22,SM[Employee ID],SM[Salesperson]) -> Ishita Verma | I22: =_xlfn.XLOOKUP(G22,SM[Employee ID],SM[Region]) -> North | J22: =_xlfn.XLOOKUP(G22,SM[Employee ID],SM[State/City]) -> Chandigarh | K22: =_xlfn.XLOOKUP(Sales[[#This Row],[Order ID]],ST[Order ID],ST[Units Sold]) -> 8 | L22: =F22*K22 -> 54000
A23: 1007 | B23: 44956 | C23: P09 | D23: =_xlfn.XLOOKUP(Merged_Sales_Data!C23,PM[Product ID],PM[Product Name]) -> USB-C Hub | E23: =VLOOKUP(C23,PM[],3,FALSE) -> Accessories | F23: =_xlfn.XLOOKUP(C23,PM[Product ID],PM[Unit Price (₹)]) -> 880 | G23: =_xlfn.XLOOKUP(Sales[[#This Row],[Order ID]],ST[Order ID],ST[Employee ID]) -> E08 | H23: =_xlfn.XLOOKUP(G23,SM[Employee ID],SM[Salesperson]) -> Neha Joshi | I23: =_xlfn.XLOOKUP(G23,SM[Employee ID],SM[Region]) -> West | J23: =_xlfn.XLOOKUP(G23,SM[Employee ID],SM[State/City]) -> Ahmedabad | K23: =_xlfn.XLOOKUP(Sales[[#This Row],[Order ID]],ST[Order ID],ST[Units Sold]) -> 1 | L23: =F23*K23 -> 880
A24: 1035 | B24: 44958 | C24: P09 | D24: =_xlfn.XLOOKUP(Merged_Sales_Data!C24,PM[Product ID],PM[Product Name]) -> USB-C Hub | E24: =VLOOKUP(C24,PM[],3,FALSE) -> Accessories | F24: =_xlfn.XLOOKUP(C24,PM[Product ID],PM[Unit Price (₹)]) -> 880 | G24: =_xlfn.XLOOKUP(Sales[[#This Row],[Order ID]],ST[Order ID],ST[Employee ID]) -> E03 | H24: =_xlfn.XLOOKUP(G24,SM[Employee ID],SM[Salesperson]) -> Rohan Mehta | I24: =_xlfn.XLOOKUP(G24,SM[Employee ID],SM[Region]) -> South | J24: =_xlfn.XLOOKUP(G24,SM[Employee ID],SM[State/City]) -> Bengaluru | K24: =_xlfn.XLOOKUP(Sales[[#This Row],[Order ID]],ST[Order ID],ST[Units Sold]) -> 6 | L24: =F24*K24 -> 5280
A25: 1037 | B25: 44959 | C25: P05 | D25: =_xlfn.XLOOKUP(Merged_Sales_Data!C25,PM[Product ID],PM[Product Name]) -> Standing Desk | E25: =VLOOKUP(C25,PM[],3,FALSE) -> Office Supplies | F25: =_xlfn.XLOOKUP(C25,PM[Product ID],PM[Unit Price (₹)]) -> 11010 | G25: =_xlfn.XLOOKUP(Sales[[#This Row],[Order ID]],ST[Order ID],ST[Employee ID]) -> E06 | H25: =_xlfn.XLOOKUP(G25,SM[Employee ID],SM[Salesperson]) -> Sneha Roy | I25: =_xlfn.XLOOKUP(G25,SM[Employee ID],SM[Region]) -> East | J25: =_xlfn.XLOOKUP(G25,SM[Employee ID],SM[State/City]) -> Kolkata | K25: =_xlfn.XLOOKUP(Sales[[#This Row],[Order ID]],ST[Order ID],ST[Units Sold]) -> 2 | L25: =F25*K25 -> 22020
A26: 1048 | B26: 44959 | C26: P04 | D26: =_xlfn.XLOOKUP(Merged_Sales_Data!C26,PM[Product ID],PM[Product Name]) -> Ergo Office Chair | E26: =VLOOKUP(C26,PM[],3,FALSE) -> Office Supplies | F26: =_xlfn.XLOOKUP(C26,PM[Product ID],PM[Unit Price (₹)]) -> 6750 | G26: =_xlfn.XLOOKUP(Sales[[#This Row],[Order ID]],ST[Order ID],ST[Employee ID]) -> E01 | H26: =_xlfn.XLOOKUP(G26,SM[Employee ID],SM[Salesperson]) -> Aarav Sharma | I26: =_xlfn.XLOOKUP(G26,SM[Employee ID],SM[Region]) -> North | J26: =_xlfn.XLOOKUP(G26,SM[Employee ID],SM[State/City]) -> Lucknow | K26: =_xlfn.XLOOKUP(Sales[[#This Row],[Order ID]],ST[Order ID],ST[Units Sold]) -> 1 | L26: =F26*K26 -> 6750
A27: 1024 | B27: 44960 | C27: P09 | D27: =_xlfn.XLOOKUP(Merged_Sales_Data!C27,PM[Product ID],PM[Product Name]) -> USB-C Hub | E27: =VLOOKUP(C27,PM[],3,FALSE) -> Accessories | F27: =_xlfn.XLOOKUP(C27,PM[Product ID],PM[Unit Price (₹)]) -> 880 | G27: =_xlfn.XLOOKUP(Sales[[#This Row],[Order ID]],ST[Order ID],ST[Employee ID]) -> E03 | H27: =_xlfn.XLOOKUP(G27,SM[Employee ID],SM[Salesperson]) -> Rohan Mehta | I27: =_xlfn.XLOOKUP(G27,SM[Employee ID],SM[Region]) -> South | J27: =_xlfn.XLOOKUP(G27,SM[Employee ID],SM[State/City]) -> Bengaluru | K27: =_xlfn.XLOOKUP(Sales[[#This Row],[Order ID]],ST[Order ID],ST[Units Sold]) -> 5 | L27: =F27*K27 -> 4400
A28: 1026 | B28: 44960 | C28: P07 | D28: =_xlfn.XLOOKUP(Merged_Sales_Data!C28,PM[Product ID],PM[Product Name]) -> Filing Cabinet | E28: =VLOOKUP(C28,PM[],3,FALSE) -> Furniture | F28: =_xlfn.XLOOKUP(C28,PM[Product ID],PM[Unit Price (₹)]) -> 4070 | G28: =_xlfn.XLOOKUP(Sales[[#This Row],[Order ID]],ST[Order ID],ST[Employee ID]) -> E03 | H28: =_xlfn.XLOOKUP(G28,SM[Employee ID],SM[Salesperson]) -> Rohan Mehta | I28: =_xlfn.XLOOKUP(G28,SM[Employee ID],SM[Region]) -> South | J28: =_xlfn.XLOOKUP(G28,SM[Employee ID],SM[State/City]) -> Bengaluru | K28: =_xlfn.XLOOKUP(Sales[[#This Row],[Order ID]],ST[Order ID],ST[Units Sold]) -> 8 | L28: =F28*K28 -> 32560
A29: 1045 | B29: 44960 | C29: P04 | D29: =_xlfn.XLOOKUP(Merged_Sales_Data!C29,PM[Product ID],PM[Product Name]) -> Ergo Office Chair | E29: =VLOOKUP(C29,PM[],3,FALSE) -> Office Supplies | F29: =_xlfn.XLOOKUP(C29,PM[Product ID],PM[Unit Price (₹)]) -> 6750 | G29: =_xlfn.XLOOKUP(Sales[[#This Row],[Order ID]],ST[Order ID],ST[Employee ID]) -> E02 | H29: =_xlfn.XLOOKUP(G29,SM[Employee ID],SM[Salesperson]) -> Ishita Verma | I29: =_xlfn.XLOOKUP(G29,SM[Employee ID],SM[Region]) -> North | J29: =_xlfn.XLOOKUP(G29,SM[Employee ID],SM[State/City]) -> Chandigarh | K29: =_xlfn.XLOOKUP(Sales[[#This Row],[Order ID]],ST[Order ID],ST[Units Sold]) -> 2 | L29: =F29*K29 -> 13500
A30: 1047 | B30: 44960 | C30: P04 | D30: =_xlfn.XLOOKUP(Merged_Sales_Data!C30,PM[Product ID],PM[Product Name]) -> Ergo Office Chair | E30: =VLOOKUP(C30,PM[],3,FALSE) -> Office Supplies | F30: =_xlfn.XLOOKUP(C30,PM[Product ID],PM[Unit Price (₹)]) -> 6750 | G30: =_xlfn.XLOOKUP(Sales[[#This Row],[Order ID]],ST[Order ID],ST[Employee ID]) -> E04 | H30: =_xlfn.XLOOKUP(G30,SM[Employee ID],SM[Salesperson]) -> Priya Nair | I30: =_xlfn.XLOOKUP(G30,SM[Employee ID],SM[Region]) -> South | J30: =_xlfn.XLOOKUP(G30,SM[Employee ID],SM[State/City]) -> Bengaluru | K30: =_xlfn.XLOOKUP(Sales[[#This Row],[Order ID]],ST[Order ID],ST[Units Sold]) -> 1 | L30: =F30*K30 -> 6750
A31: 1036 | B31: 44961 | C31: P08 | D31: =_xlfn.XLOOKUP(Merged_Sales_Data!C31,PM[Product ID],PM[Product Name]) -> Laptop Backpack | E31: =VLOOKUP(C31,PM[],3,FALSE) -> Accessories | F31: =_xlfn.XLOOKUP(C31,PM[Product ID],PM[Unit Price (₹)]) -> 1110 | G31: =_xlfn.XLOOKUP(Sales[[#This Row],[Order ID]],ST[Order ID],ST[Employee ID]) -> E06 | H31: =_xlfn.XLOOKUP(G31,SM[Employee ID],SM[Salesperson]) -> Sneha Roy | I31: =_xlfn.XLOOKUP(G31,SM[Employee ID],SM[Region]) -> East | J31: =_xlfn.XLOOKUP(G31,SM[Employee ID],SM[State/City]) -> Kolkata | K31: =_xlfn.XLOOKUP(Sales[[#This Row],[Order ID]],ST[Order ID],ST[Units Sold]) -> 1 | L31: =F31*K31 -> 1110
... A743: 1726 | B743: 45657 | C743: P07 | D743: =_xlfn.XLOOKUP(Merged_Sales_Data!C743,PM[Product ID],PM[Product Name]) -> Filing Cabinet | E743: =VLOOKUP(C743,PM[],3,FALSE) -> Furniture | F743: =_xlfn.XLOOKUP(C743,PM[Product ID],PM[Unit Price (₹)]) -> 4070 | G743: =_xlfn.XLOOKUP(Sales[[#This Row],[Order ID]],ST[Order ID],ST[Employee ID]) -> E01 | H743: =_xlfn.XLOOKUP(G743,SM[Employee ID],SM[Salesperson]) -> Aarav Sharma | I743: =_xlfn.XLOOKUP(G743,SM[Employee ID],SM[Region]) -> North | J743: =_xlfn.XLOOKUP(G743,SM[Employee ID],SM[State/City]) -> Lucknow | K743: =_xlfn.XLOOKUP(Sales[[#This Row],[Order ID]],ST[Order ID],ST[Units Sold]) -> 3 | L743: =F743*K743 -> 12210

Sheet MyTable
A1: Order ID | B1: Order Date | C1: Product ID | D1: Product Name | E1: Category | F1: Unit Price (₹) | G1: Employee ID | H1: Salesperson | I1: Region | J1: State/City | K1: Units Sold | L1: Revenue (₹)
A2: 1009 | B2: 44928 | C2: P04 | D2: =_xlfn.XLOOKUP(Merged_Sales_Data!C2,PM[Product ID],PM[Product Name]) -> Ergo Office Chair | E2: =VLOOKUP(C2,PM[],3,FALSE) -> Office Supplies | F2: =_xlfn.XLOOKUP(C2,PM[Product ID],PM[Unit Price (₹)]) -> 6750 | G2: E07 | H2: =_xlfn.XLOOKUP(G2,SM[Employee ID],SM[Salesperson]) -> Aditya Kapoor | I2: =_xlfn.XLOOKUP(G2,SM[Employee ID],SM[Region]) -> West | J2: =_xlfn.XLOOKUP(G2,SM[Employee ID],SM[State/City]) -> Mumbai | K2: 1 | L2: =F2*K2 -> 6750
A3: 1004 | B3: 44930 | C3: P04 | D3: =_xlfn.XLOOKUP(Merged_Sales_Data!C3,PM[Product ID],PM[Product Name]) -> Ergo Office Chair | E3: =VLOOKUP(C3,PM[],3,FALSE) -> Office Supplies | F3: =_xlfn.XLOOKUP(C3,PM[Product ID],PM[Unit Price (₹)]) -> 6750 | G3: E06 | H3: =_xlfn.XLOOKUP(G3,SM[Employee ID],SM[Salesperson]) -> Sneha Roy | I3: =_xlfn.XLOOKUP(G3,SM[Employee ID],SM[Region]) -> East | J3: =_xlfn.XLOOKUP(G3,SM[Employee ID],SM[State/City]) -> Kolkata | K3: 1 | L3: =F3*K3 -> 6750
A4: 1001 | B4: 44934 | C4: P09 | D4: =_xlfn.XLOOKUP(Merged_Sales_Data!C4,PM[Product ID],PM[Product Name]) -> USB-C Hub | E4: =VLOOKUP(C4,PM[],3,FALSE) -> Accessories | F4: =_xlfn.XLOOKUP(C4,PM[Product ID],PM[Unit Price (₹)]) -> 880 | G4: E08 | H4: =_xlfn.XLOOKUP(G4,SM[Employee ID],SM[Salesperson]) -> Neha Joshi | I4: =_xlfn.XLOOKUP(G4,SM[Employee ID],SM[Region]) -> West | J4: =_xlfn.XLOOKUP(G4,SM[Employee ID],SM[State/City]) -> Ahmedabad | K4: 6 | L4: =F4*K4 -> 5280
A5: 1003 | B5: 44935 | C5: P07 | D5: =_xlfn.XLOOKUP(Merged_Sales_Data!C5,PM[Product ID],PM[Product Name]) -> Filing Cabinet | E5: =VLOOKUP(C5,PM[],3,FALSE) -> Furniture | F5: =_xlfn.XLOOKUP(C5,PM[Product ID],PM[Unit Price (₹)]) -> 4070 | G5: E08 | H5: =_xlfn.XLOOKUP(G5,SM[Employee ID],SM[Salesperson]) -> Neha Joshi | I5: =_xlfn.XLOOKUP(G5,SM[Employee ID],SM[Region]) -> West | J5: =_xlfn.XLOOKUP(G5,SM[Employee ID],SM[State/City]) -> Ahmedabad | K5: 6 | L5: =F5*K5 -> 24420
A6: 1011 | B6: 44935 | C6: P02 | D6: =_xlfn.XLOOKUP(Merged_Sales_Data!C6,PM[Product ID],PM[Product Name]) -> Bluetooth Speaker | E6: =VLOOKUP(C6,PM[],3,FALSE) -> Electronics | F6: =_xlfn.XLOOKUP(C6,PM[Product ID],PM[Unit Price (₹)]) -> 1430 | G6: E06 | H6: =_xlfn.XLOOKUP(G6,SM[Employee ID],SM[Salesperson]) -> Sneha Roy | I6: =_xlfn.XLOOKUP(G6,SM[Employee ID],SM[Region]) -> East | J6: =_xlfn.XLOOKUP(G6,SM[Employee ID],SM[State/City]) -> Kolkata | K6: 10 | L6: =F6*K6 -> 14300
A7: 1013 | B7: 44935 | C7: P04 | D7: =_xlfn.XLOOKUP(Merged_Sales_Data!C7,PM[Product ID],PM[Product Name]) -> Ergo Office Chair | E7: =VLOOKUP(C7,PM[],3,FALSE) -> Office Supplies | F7: =_xlfn.XLOOKUP(C7,PM[Product ID],PM[Unit Price (₹)]) -> 6750 | G7: E06 | H7: =_xlfn.XLOOKUP(G7,SM[Employee ID],SM[Salesperson]) -> Sneha Roy | I7: =_xlfn.XLOOKUP(G7,SM[Employee ID],SM[Region]) -> East | J7: =_xlfn.XLOOKUP(G7,SM[Employee ID],SM[State/City]) -> Kolkata | K7: 8 | L7: =F7*K7 -> 54000
A8: 1018 | B8: 44935 | C8: P06 | D8: =_xlfn.XLOOKUP(Merged_Sales_Data!C8,PM[Product ID],PM[Product Name]) -> Bookshelf Unit | E8: =VLOOKUP(C8,PM[],3,FALSE) -> Furniture | F8: =_xlfn.XLOOKUP(C8,PM[Product ID],PM[Unit Price (₹)]) -> 3910 | G8: E08 | H8: =_xlfn.XLOOKUP(G8,SM[Employee ID],SM[Salesperson]) -> Neha Joshi | I8: =_xlfn.XLOOKUP(G8,SM[Employee ID],SM[Region]) -> West | J8: =_xlfn.XLOOKUP(G8,SM[Employee ID],SM[State/City]) -> Ahmedabad | K8: 4 | L8: =F8*K8 -> 15640
A9: 1021 | B9: 44935 | C9: P08 | D9: =_xlfn.XLOOKUP(Merged_Sales_Data!C9,PM[Product ID],PM[Product Name]) -> Laptop Backpack | E9: =VLOOKUP(C9,PM[],3,FALSE) -> Accessories | F9: =_xlfn.XLOOKUP(C9,PM[Product ID],PM[Unit Price (₹)]) -> 1110 | G9: E04 | H9: =_xlfn.XLOOKUP(G9,SM[Employee ID],SM[Salesperson]) -> Priya Nair | I9: =_xlfn.XLOOKUP(G9,SM[Employee ID],SM[Region]) -> South | J9: =_xlfn.XLOOKUP(G9,SM[Employee ID],SM[State/City]) -> Bengaluru | K9: 1 | L9: =F9*K9 -> 1110
A10: 1008 | B10: 44936 | C10: P02 | D10: =_xlfn.XLOOKUP(Merged_Sales_Data!C10,PM[Product ID],PM[Product Name]) -> Bluetooth Speaker | E10: =VLOOKUP(C10,PM[],3,FALSE) -> Electronics | F10: =_xlfn.XLOOKUP(C10,PM[Product ID],PM[Unit Price (₹)]) -> 1430 | G10: E05 | H10: =_xlfn.XLOOKUP(G10,SM[Employee ID],SM[Salesperson]) -> Karan Malhotra | I10: =_xlfn.XLOOKUP(G10,SM[Employee ID],SM[Region]) -> East | J10: =_xlfn.XLOOKUP(G10,SM[Employee ID],SM[State/City]) -> Kolkata | K10: 4 | L10: =F10*K10 -> 5720
A11: 1005 | B11: 44938 | C11: P07 | D11: =_xlfn.XLOOKUP(Merged_Sales_Data!C11,PM[Product ID],PM[Product Name]) -> Filing Cabinet | E11: =VLOOKUP(C11,PM[],3,FALSE) -> Furniture | F11: =_xlfn.XLOOKUP(C11,PM[Product ID],PM[Unit Price (₹)]) -> 4070 | G11: E02 | H11: =_xlfn.XLOOKUP(G11,SM[Employee ID],SM[Salesperson]) -> Ishita Verma | I11: =_xlfn.XLOOKUP(G11,SM[Employee ID],SM[Region]) -> North | J11: =_xlfn.XLOOKUP(G11,SM[Employee ID],SM[State/City]) -> Chandigarh | K11: 2 | L11: =F11*K11 -> 8140
A12: 1012 | B12: 44938 | C12: P06 | D12: =_xlfn.XLOOKUP(Merged_Sales_Data!C12,PM[Product ID],PM[Product Name]) -> Bookshelf Unit | E12: =VLOOKUP(C12,PM[],3,FALSE) -> Furniture | F12: =_xlfn.XLOOKUP(C12,PM[Product ID],PM[Unit Price (₹)]) -> 3910 | G12: E03 | H12: =_xlfn.XLOOKUP(G12,SM[Employee ID],SM[Salesperson]) -> Rohan Mehta | I12: =_xlfn.XLOOKUP(G12,SM[Employee ID],SM[Region]) -> South | J12: =_xlfn.XLOOKUP(G12,SM[Employee ID],SM[State/City]) -> Bengaluru | K12: 10 | L12: =F12*K12 -> 39100
A13: 1015 | B13: 44939 | C13: P03 | D13: =_xlfn.XLOOKUP(Merged_Sales_Data!C13,PM[Product ID],PM[Product Name]) -> LED Monitor 24" | E13: =VLOOKUP(C13,PM[],3,FALSE) -> Electronics | F13: =_xlfn.XLOOKUP(C13,PM[Product ID],PM[Unit Price (₹)]) -> 7700 | G13: E07 | H13: =_xlfn.XLOOKUP(G13,SM[Employee ID],SM[Salesperson]) -> Aditya Kapoor | I13: =_xlfn.XLOOKUP(G13,SM[Employee ID],SM[Region]) -> West | J13: =_xlfn.XLOOKUP(G13,SM[Employee ID],SM[State/City]) -> Mumbai | K13: 2 | L13: =F13*K13 -> 15400
... A19: 1002 | B19: 44951 | C19: P05 | D19: =_xlfn.XLOOKUP(Merged_Sales_Data!C19,PM[Product ID],PM[Product Name]) -> Standing Desk | E19: =VLOOKUP(C19,PM[],3,FALSE) -> Office Supplies | F19: =_xlfn.XLOOKUP(C19,PM[Product ID],PM[Unit Price (₹)]) -> 11010 | G19: E01 | H19: =_xlfn.XLOOKUP(G19,SM[Employee ID],SM[Salesperson]) -> Aarav Sharma | I19: =_xlfn.XLOOKUP(G19,SM[Employee ID],SM[Region]) -> North | J19: =_xlfn.XLOOKUP(G19,SM[Employee ID],SM[State/City]) -> Lucknow | K19: 3 | L19: =F19*K19 -> 33030
A20: 1017 | B20: 44953 | C20: P01 | D20: =_xlfn.XLOOKUP(Merged_Sales_Data!C20,PM[Product ID],PM[Product Name]) -> Wireless Mouse | E20: =VLOOKUP(C20,PM[],3,FALSE) -> Electronics | F20: =_xlfn.XLOOKUP(C20,PM[Product ID],PM[Unit Price (₹)]) -> 780 | G20: =_xlfn.XLOOKUP(Sales7[[#This Row],[Order ID]],ST[Order ID],ST[Employee ID]) -> E06 | H20: =_xlfn.XLOOKUP(G20,SM[Employee ID],SM[Salesperson]) -> Sneha Roy | I20: =_xlfn.XLOOKUP(G20,SM[Employee ID],SM[Region]) -> East | J20: =_xlfn.XLOOKUP(G20,SM[Employee ID],SM[State/City]) -> Kolkata | K20: =_xlfn.XLOOKUP(Sales7[[#This Row],[Order ID]],ST[Order ID],ST[Units Sold]) -> 2 | L20: =F20*K20 -> 1560
A21: 1010 | B21: 44954 | C21: P05 | D21: =_xlfn.XLOOKUP(Merged_Sales_Data!C21,PM[Product ID],PM[Product Name]) -> Standing Desk | E21: =VLOOKUP(C21,PM[],3,FALSE) -> Office Supplies | F21: =_xlfn.XLOOKUP(C21,PM[Product ID],PM[Unit Price (₹)]) -> 11010 | G21: =_xlfn.XLOOKUP(Sales7[[#This Row],[Order ID]],ST[Order ID],ST[Employee ID]) -> E04 | H21: =_xlfn.XLOOKUP(G21,SM[Employee ID],SM[Salesperson]) -> Priya Nair | I21: =_xlfn.XLOOKUP(G21,SM[Employee ID],SM[Region]) -> South | J21: =_xlfn.XLOOKUP(G21,SM[Employee ID],SM[State/City]) -> Bengaluru | K21: =_xlfn.XLOOKUP(Sales7[[#This Row],[Order ID]],ST[Order ID],ST[Units Sold]) -> 1 | L21: =F21*K21 -> 11010
A22: 1019 | B22: 44955 | C22: P04 | D22: =_xlfn.XLOOKUP(Merged_Sales_Data!C22,PM[Product ID],PM[Product Name]) -> Ergo Office Chair | E22: =VLOOKUP(C22,PM[],3,FALSE) -> Office Supplies | F22: =_xlfn.XLOOKUP(C22,PM[Product ID],PM[Unit Price (₹)]) -> 6750 | G22: =_xlfn.XLOOKUP(Sales7[[#This Row],[Order ID]],ST[Order ID],ST[Employee ID]) -> E02 | H22: =_xlfn.XLOOKUP(G22,SM[Employee ID],SM[Salesperson]) -> Ishita Verma | I22: =_xlfn.XLOOKUP(G22,SM[Employee ID],SM[Region]) -> North | J22: =_xlfn.XLOOKUP(G22,SM[Employee ID],SM[State/City]) -> Chandigarh | K22: =_xlfn.XLOOKUP(Sales7[[#This Row],[Order ID]],ST[Order ID],ST[Units Sold]) -> 8 | L22: =F22*K22 -> 54000
A23: 1007 | B23: 44956 | C23: P09 | D23: =_xlfn.XLOOKUP(Merged_Sales_Data!C23,PM[Product ID],PM[Product Name]) -> USB-C Hub | E23: =VLOOKUP(C23,PM[],3,FALSE) -> Accessories | F23: =_xlfn.XLOOKUP(C23,PM[Product ID],PM[Unit Price (₹)]) -> 880 | G23: =_xlfn.XLOOKUP(Sales7[[#This Row],[Order ID]],ST[Order ID],ST[Employee ID]) -> E08 | H23: =_xlfn.XLOOKUP(G23,SM[Employee ID],SM[Salesperson]) -> Neha Joshi | I23: =_xlfn.XLOOKUP(G23,SM[Employee ID],SM[Region]) -> West | J23: =_xlfn.XLOOKUP(G23,SM[Employee ID],SM[State/City]) -> Ahmedabad | K23: =_xlfn.XLOOKUP(Sales7[[#This Row],[Order ID]],ST[Order ID],ST[Units Sold]) -> 1 | L23: =F23*K23 -> 880
A24: 1035 | B24: 44958 | C24: P09 | D24: =_xlfn.XLOOKUP(Merged_Sales_Data!C24,PM[Product ID],PM[Product Name]) -> USB-C Hub | E24: =VLOOKUP(C24,PM[],3,FALSE) -> Accessories | F24: =_xlfn.XLOOKUP(C24,PM[Product ID],PM[Unit Price (₹)]) -> 880 | G24: =_xlfn.XLOOKUP(Sales7[[#This Row],[Order ID]],ST[Order ID],ST[Employee ID]) -> E03 | H24: =_xlfn.XLOOKUP(G24,SM[Employee ID],SM[Salesperson]) -> Rohan Mehta | I24: =_xlfn.XLOOKUP(G24,SM[Employee ID],SM[Region]) -> South | J24: =_xlfn.XLOOKUP(G24,SM[Employee ID],SM[State/City]) -> Bengaluru | K24: =_xlfn.XLOOKUP(Sales7[[#This Row],[Order ID]],ST[Order ID],ST[Units Sold]) -> 6 | L24: =F24*K24 -> 5280
A25: 1037 | B25: 44959 | C25: P05 | D25: =_xlfn.XLOOKUP(Merged_Sales_Data!C25,PM[Product ID],PM[Product Name]) -> Standing Desk | E25: =VLOOKUP(C25,PM[],3,FALSE) -> Office Supplies | F25: =_xlfn.XLOOKUP(C25,PM[Product ID],PM[Unit Price (₹)]) -> 11010 | G25: =_xlfn.XLOOKUP(Sales7[[#This Row],[Order ID]],ST[Order ID],ST[Employee ID]) -> E06 | H25: =_xlfn.XLOOKUP(G25,SM[Employee ID],SM[Salesperson]) -> Sneha Roy | I25: =_xlfn.XLOOKUP(G25,SM[Employee ID],SM[Region]) -> East | J25: =_xlfn.XLOOKUP(G25,SM[Employee ID],SM[State/City]) -> Kolkata | K25: =_xlfn.XLOOKUP(Sales7[[#This Row],[Order ID]],ST[Order ID],ST[Units Sold]) -> 2 | L25: =F25*K25 -> 22020
A26: 1048 | B26: 44959 | C26: P04 | D26: =_xlfn.XLOOKUP(Merged_Sales_Data!C26,PM[Product ID],PM[Product Name]) -> Ergo Office Chair | E26: =VLOOKUP(C26,PM[],3,FALSE) -> Office Supplies | F26: =_xlfn.XLOOKUP(C26,PM[Product ID],PM[Unit Price (₹)]) -> 6750 | G26: =_xlfn.XLOOKUP(Sales7[[#This Row],[Order ID]],ST[Order ID],ST[Employee ID]) -> E01 | H26: =_xlfn.XLOOKUP(G26,SM[Employee ID],SM[Salesperson]) -> Aarav Sharma | I26: =_xlfn.XLOOKUP(G26,SM[Employee ID],SM[Region]) -> North | J26: =_xlfn.XLOOKUP(G26,SM[Employee ID],SM[State/City]) -> Lucknow | K26: =_xlfn.XLOOKUP(Sales7[[#This Row],[Order ID]],ST[Order ID],ST[Units Sold]) -> 1 | L26: =F26*K26 -> 6750
A27: 1024 | B27: 44960 | C27: P09 | D27: =_xlfn.XLOOKUP(Merged_Sales_Data!C27,PM[Product ID],PM[Product Name]) -> USB-C Hub | E27: =VLOOKUP(C27,PM[],3,FALSE) -> Accessories | F27: =_xlfn.XLOOKUP(C27,PM[Product ID],PM[Unit Price (₹)]) -> 880 | G27: =_xlfn.XLOOKUP(Sales7[[#This Row],[Order ID]],ST[Order ID],ST[Employee ID]) -> E03 | H27: =_xlfn.XLOOKUP(G27,SM[Employee ID],SM[Salesperson]) -> Rohan Mehta | I27: =_xlfn.XLOOKUP(G27,SM[Employee ID],SM[Region]) -> South | J27: =_xlfn.XLOOKUP(G27,SM[Employee ID],SM[State/City]) -> Bengaluru | K27: =_xlfn.XLOOKUP(Sales7[[#This Row],[Order ID]],ST[Order ID],ST[Units Sold]) -> 5 | L27: =F27*K27 -> 4400
A28: 1026 | B28: 44960 | C28: P07 | D28: =_xlfn.XLOOKUP(Merged_Sales_Data!C28,PM[Product ID],PM[Product Name]) -> Filing Cabinet | E28: =VLOOKUP(C28,PM[],3,FALSE) -> Furniture | F28: =_xlfn.XLOOKUP(C28,PM[Product ID],PM[Unit Price (₹)]) -> 4070 | G28: =_xlfn.XLOOKUP(Sales7[[#This Row],[Order ID]],ST[Order ID],ST[Employee ID]) -> E03 | H28: =_xlfn.XLOOKUP(G28,SM[Employee ID],SM[Salesperson]) -> Rohan Mehta | I28: =_xlfn.XLOOKUP(G28,SM[Employee ID],SM[Region]) -> South | J28: =_xlfn.XLOOKUP(G28,SM[Employee ID],SM[State/City]) -> Bengaluru | K28: =_xlfn.XLOOKUP(Sales7[[#This Row],[Order ID]],ST[Order ID],ST[Units Sold]) -> 8 | L28: =F28*K28 -> 32560
A29: 1045 | B29: 44960 | C29: P04 | D29: =_xlfn.XLOOKUP(Merged_Sales_Data!C29,PM[Product ID],PM[Product Name]) -> Ergo Office Chair | E29: =VLOOKUP(C29,PM[],3,FALSE) -> Office Supplies | F29: =_xlfn.XLOOKUP(C29,PM[Product ID],PM[Unit Price (₹)]) -> 6750 | G29: =_xlfn.XLOOKUP(Sales7[[#This Row],[Order ID]],ST[Order ID],ST[Employee ID]) -> E02 | H29: =_xlfn.XLOOKUP(G29,SM[Employee ID],SM[Salesperson]) -> Ishita Verma | I29: =_xlfn.XLOOKUP(G29,SM[Employee ID],SM[Region]) -> North | J29: =_xlfn.XLOOKUP(G29,SM[Employee ID],SM[State/City]) -> Chandigarh | K29: =_xlfn.XLOOKUP(Sales7[[#This Row],[Order ID]],ST[Order ID],ST[Units Sold]) -> 2 | L29: =F29*K29 -> 13500
A30: 1047 | B30: 44960 | C30: P04 | D30: =_xlfn.XLOOKUP(Merged_Sales_Data!C30,PM[Product ID],PM[Product Name]) -> Ergo Office Chair | E30: =VLOOKUP(C30,PM[],3,FALSE) -> Office Supplies | F30: =_xlfn.XLOOKUP(C30,PM[Product ID],PM[Unit Price (₹)]) -> 6750 | G30: =_xlfn.XLOOKUP(Sales7[[#This Row],[Order ID]],ST[Order ID],ST[Employee ID]) -> E04 | H30: =_xlfn.XLOOKUP(G30,SM[Employee ID],SM[Salesperson]) -> Priya Nair | I30: =_xlfn.XLOOKUP(G30,SM[Employee ID],SM[Region]) -> South | J30: =_xlfn.XLOOKUP(G30,SM[Employee ID],SM[State/City]) -> Bengaluru | K30: =_xlfn.XLOOKUP(Sales7[[#This Row],[Order ID]],ST[Order ID],ST[Units Sold]) -> 1 | L30: =F30*K30 -> 6750
A31: 1036 | B31: 44961 | C31: P08 | D31: =_xlfn.XLOOKUP(Merged_Sales_Data!C31,PM[Product ID],PM[Product Name]) -> Laptop Backpack | E31: =VLOOKUP(C31,PM[],3,FALSE) -> Accessories | F31: =_xlfn.XLOOKUP(C31,PM[Product ID],PM[Unit Price (₹)]) -> 1110 | G31: =_xlfn.XLOOKUP(Sales7[[#This Row],[Order ID]],ST[Order ID],ST[Employee ID]) -> E06 | H31: =_xlfn.XLOOKUP(G31,SM[Employee ID],SM[Salesperson]) -> Sneha Roy | I31: =_xlfn.XLOOKUP(G31,SM[Employee ID],SM[Region]) -> East | J31: =_xlfn.XLOOKUP(G31,SM[Employee ID],SM[State/City]) -> Kolkata | K31: =_xlfn.XLOOKUP(Sales7[[#This Row],[Order ID]],ST[Order ID],ST[Units Sold]) -> 1 | L31: =F31*K31 -> 1110
... A743: 1726 | B743: 45657 | C743: P07 | D743: =_xlfn.XLOOKUP(Merged_Sales_Data!C743,PM[Product ID],PM[Product Name]) -> Filing Cabinet | E743: =VLOOKUP(C743,PM[],3,FALSE) -> Furniture | F743: =_xlfn.XLOOKUP(C743,PM[Product ID],PM[Unit Price (₹)]) -> 4070 | G743: =_xlfn.XLOOKUP(Sales7[[#This Row],[Order ID]],ST[Order ID],ST[Employee ID]) -> E01 | H743: =_xlfn.XLOOKUP(G743,SM[Employee ID],SM[Salesperson]) -> Aarav Sharma | I743: =_xlfn.XLOOKUP(G743,SM[Employee ID],SM[Region]) -> North | J743: =_xlfn.XLOOKUP(G743,SM[Employee ID],SM[State/City]) -> Lucknow | K743: =_xlfn.XLOOKUP(Sales7[[#This Row],[Order ID]],ST[Order ID],ST[Units Sold]) -> 3 | L743: =F743*K743 -> 12210

Sheet Read_Me
B2: Sales Dashboard — Normalized Sample Data (for VLOOKUP/XLOOKUP/INDEX-MATCH practice)
B4: Purpose
B5: This workbook splits the data across separate sheets, the way real MIS/ERP exports
B6: usually look, so you can practise joining them with VLOOKUP, XLOOKUP or INDEX-MATCH.
B8: Sheets
B9: • Sales_Transactions — the FACT table. One row per order: Order ID, Date, Product ID,
B10: Employee ID, Units Sold. Deliberately has NO product name,
B11: price, salesperson name or region — you'll pull those in.
B12: • Product_Master — lookup table: Product ID -> Product Name, Category, Unit Price.
B13: • Salesperson_Master — lookup table: Employee ID -> Salesperson, Region, State/City.
B14: • Monthly_Targets — Region-wise revenue target per month (for later variance work).
B15: • Merged_Sales_Data — empty scaffold with the final column headers already laid out.
... B27: Note: All names, IDs and figures are fictional, generated for practice.

Sheet Summary
A1: Sum of Revenue (₹)
A2: Category | B2: Total
A3: Accessories | B3: 15190
A4: Electronics | B4: 43120
A5: Furniture | B5: 87300
A6: Office Supplies | B6: 158790
A7: Grand Total | B7: 304400
A11: Sum of Revenue (₹)
A12: Region | B12: Total
A13: East | B13: 130070
A14: North | B14: 48870
A15: South | B15: 40210
A16: West | B16: 85250
A17: (blank)
A18: Grand Total | B18: 304400
C22: Values
A23: Product ID | B23: Product Name | C23: Sum of Units Sold | D23: Sum of Revenue (₹) | E23: Average of Unit Price (₹)
A24: P01 | B24: Wireless Mouse | E24: 780
A25: P01 Total | E25: 780
A26: P02 | B26: Bluetooth Speaker | C26: 14 | D26: 20020 | E26: 1430
A27: P02 Total | C27: 14 | D27: 20020 | E27: 1430
A28: P03 | B28: LED Monitor 24" | C28: 3 | D28: 23100 | E28: 7700
A29: P03 Total | C29: 3 | D29: 23100 | E29: 7700
A30: P04 | B30: Ergo Office Chair | C30: 17 | D30: 114750 | E30: 6750
A31: P04 Total | C31: 17 | D31: 114750 | E31: 6750
A32: P05 | B32: Standing Desk | C32: 4 | D32: 44040 | E32: 11010
A33: P05 Total | C33: 4 | D33: 44040 | E33: 11010
A34: P06 | B34: Bookshelf Unit | C34: 14 | D34: 54740 | E34: 3910
A35: P06 Total | C35: 14 | D35: 54740 | E35: 3910
A36: P07 | B36: Filing Cabinet | C36: 8 | D36: 32560 | E36: 4070
A37: P07 Total | C37: 8 | D37: 32560 | E37: 4070
A38: P08 | B38: Laptop Backpack | C38: 1 | D38: 1110 | E38: 1110
A39: P08 Total | C39: 1 | D39: 1110 | E39: 1110
A40: P09 | B40: USB-C Hub | C40: 16 | D40: 14080 | E40: 880
A41: P09 Total | C41: 16 | D41: 14080 | E41: 880
A42: Grand Total | C42: 77 | D42: 304400 | E42: 4188.4097
A45: Sum of Revenue (₹) | B45: Months (Order Date)
A46: Region | B46: Jan | C46: Feb | D46: Mar | E46: Apr | F46: May | G46: Jun | H46: Jul | I46: Aug | J46: Sep | K46: Oct | L46: Nov | M46: Dec | N46: Grand Total
A47: East | B47: 235880 | C47: 114170 | D47: 228960 | E47: 392260 | F47: 85790 | G47: 326390 | H47: 84740 | I47: 310850 | J47: 149740 | K47: 241260 | L47: 421910 | M47: 208830 | N47: 2800780
A48: North | B48: 162790 | C48: 248750 | D48: 173130 | E48: 174540 | F48: 349300 | G48: 225590 | H48: 348080 | I48: 219230 | J48: 304200 | K48: 377700 | L48: 317660 | M48: 103400 | N48: 3004370
...

Sheet Dashboard
I24: Region
I25: East
I26: North
I27: South
I28: West
